    parity=self.parity)
  File "/usr/lib/python3/dist-packages/serial/serialutil.py", line 240, in __init__
    self.open()
  File "/usr/lib/python3/dist-packages/serial/serialposix.py", line 286, in open
    self._update_dtr_state()
  File "/usr/lib/python3/dist-packages/serial/serialposix.py", line 634, in _update_dtr_state
    fcntl.ioctl(self.fd, TIOCMBIS, TIOCM_DTR_str)
OSError: [Errno 5] Input/output error
2020-01-24 18:38:15.207 | 1020089 | ERROR | brokkr.sunsaver | OSError connecting to charge controller device /dev/ttyUSB0: [Errno 5] Input/output error
2020-01-24 18:38:15.208 | 1020090 | INFO | brokkr.sunsaver | Details: ModbusSerialClient(rtu baud[9600])
Traceback (most recent call last):
  File "/home/thor/dev/brokkr/src/brokkr/sunsaver.py", line 161, in read_raw_sunsaver_data
    connect_successful = mppt_client.connect()
  File "/home/thor/dev/brokkrenv/lib/python3.7/site-packages/pymodbus/client/sync.py", line 481, in connect
    parity=self.parity)
  File "/usr/lib/python3/dist-packages/serial/serialutil.py", line 240, in __init__
    self.open()
  File "/usr/lib/python3/dist-packages/serial/serialposix.py", line 286, in open
    self._update_dtr_state()
  File "/usr/lib/python3/dist-packages/serial/serialposix.py", line 634, in _update_dtr_state
    fcntl.ioctl(self.fd, TIOCMBIS, TIOCM_DTR_str)
OSError: [Errno 5] Input/output error
2020-01-24 18:38:36.318 | 1041200 | INFO | brokkr.startup | Interrupted by signal 15; terminating Brokkr
2020-01-24 19:43:42.009 | 47 | INFO | brokkr.startup | Starting Brokkr...
2020-01-25 00:39:46.061 | 17764099 | ERROR | brokkr.sunsaver | ModbusIOException reading register data for /dev/ttyUSB0: Modbus Error: [Input/Output] Modbus Error: [Invalid Message] Incomplete message received, expected at least 2 bytes (0 received)
2020-01-25 00:39:46.062 | 17764100 | INFO | brokkr.sunsaver | Details: ModbusSerialClient(rtu baud[9600])
Traceback (most recent call last):
  File "/home/thor/dev/brokkr/src/brokkr/sunsaver.py", line 167, in read_raw_sunsaver_data
    raise register_data
pymodbus.exceptions.ModbusIOException: Modbus Error: [Input/Output] Modbus Error: [Invalid Message] Incomplete message received, expected at least 2 bytes (0 received)
