    fcntl.ioctl(self.fd, TIOCMBIS, TIOCM_DTR_str)
OSError: [Errno 5] Input/output error
2020-01-24 17:12:54.013 | 260941134 | ERROR | brokkr.sunsaver | OSError connecting to charge controller device /dev/ttyUSB0: [Errno 5] Input/output error
2020-01-24 17:12:54.014 | 260941136 | INFO | brokkr.sunsaver | Details: ModbusSerialClient(rtu baud[9600])
Traceback (most recent call last):
  File "/home/thor/dev/brokkr/src/brokkr/sunsaver.py", line 161, in read_raw_sunsaver_data
    connect_successful = mppt_client.connect()
  File "/home/thor/dev/brokkrenv/lib/python3.7/site-packages/pymodbus/client/sync.py", line 481, in connect
    parity=self.parity)
  File "/usr/lib/python3/dist-packages/serial/serialutil.py", line 240, in __init__
    self.open()
  File "/usr/lib/python3/dist-packages/serial/serialposix.py", line 286, in open
    self._update_dtr_state()
  File "/usr/lib/python3/dist-packages/serial/serialposix.py", line 634, in _update_dtr_state
    fcntl.ioctl(self.fd, TIOCMBIS, TIOCM_DTR_str)
OSError: [Errno 5] Input/output error
2020-01-24 17:13:54.013 | 261001134 | ERROR | brokkr.sunsaver | OSError connecting to charge controller device /dev/ttyUSB0: [Errno 5] Input/output error
2020-01-24 17:13:54.014 | 261001136 | INFO | brokkr.sunsaver | Details: ModbusSerialClient(rtu baud[9600])
Traceback (most recent call last):
  File "/home/thor/dev/brokkr/src/brokkr/sunsaver.py", line 161, in read_raw_sunsaver_data
    connect_successful = mppt_client.connect()
  File "/home/thor/dev/brokkrenv/lib/python3.7/site-packages/pymodbus/client/sync.py", line 481, in connect
    parity=self.parity)
  File "/usr/lib/python3/dist-packages/serial/serialutil.py", line 240, in __init__
    self.open()
  File "/usr/lib/python3/dist-packages/serial/serialposix.py", line 286, in open
    self._update_dtr_state()
  File "/usr/lib/python3/dist-packages/serial/serialposix.py", line 634, in _update_dtr_state
    fcntl.ioctl(self.fd, TIOCMBIS, TIOCM_DTR_str)
OSError: [Errno 5] Input/output error
